INFO 2016-06-16 14:49:46,574 tasks 89513 140735228776448 /Users/tao-xu/Downloads/vCenter/paas/applications/stat/tasks.py 22 test_con yesyesyysysysysyysysys
INFO 2016-06-16 18:56:47,825 tasks 89513 140735228776448 /Users/tao-xu/Downloads/vCenter/paas/applications/stat/tasks.py 84 vm_to_tpl start vm:1000008406-redhat5.964-20160616150934-B71XDKFK to tpl:CDS-OS-Redhat5.9-64bit-General-Vffbc1ee0-33b0-11e6-9081-507b9d5bc407
INFO 2016-06-16 18:59:00,080 tasks 89513 140735228776448 /Users/tao-xu/Downloads/vCenter/paas/applications/stat/tasks.py 91 vm_to_tpl template_id is e1ed7072-df67-49c6-9006-18b72b2f3337
INFO 2016-06-17 10:35:39,298 tasks 89513 140735228776448 /Users/tao-xu/Downloads/vCenter/paas/applications/stat/tasks.py 84 vm_to_tpl start vm:None to tpl:CDS-OS-Redhat5.9-64bit-General-V00284716-33b4-11e6-bc0e-507b9d5bc407
INFO 2016-06-17 13:32:18,283 tasks 89513 140735228776448 /Users/tao-xu/Downloads/vCenter/paas/applications/stat/tasks.py 84 vm_to_tpl start vm:None to tpl:CDS-OS-Redhat5.9-64bit-General-V00284716-33b4-11e6-bc0e-507b9d5bc407
INFO 2016-06-17 13:33:33,596 tasks 89513 140735228776448 /Users/tao-xu/Downloads/vCenter/paas/applications/stat/tasks.py 111 vm_to_tpl vm_to_tpl when catch exception:Traceback (most recent call last):
  File "/Users/tao-xu/Downloads/vCenter/paas/applications/stat/tasks.py", line 86, in vm_to_tpl
    datacenter_name=data_center, cluster=cluster, datastore=data_store)
  File "/Users/tao-xu/Downloads/vCenter/paas/libs/vcenter.py", line 318, in vm_to_template
    si = connect_vcenter(host=host, username=username, password=password)
  File "/Users/tao-xu/Downloads/vCenter/paas/libs/vcenter.py", line 133, in connect_vcenter
    si = SmartConnect(host=host, user=username, pwd=password, port=443, sslContext=CONTEXT)
  File "/Users/tao-xu/.virtualenvs/test_vcenter/lib/python2.7/site-packages/pyVim/connect.py", line 663, in SmartConnect
    sslContext)
  File "/Users/tao-xu/.virtualenvs/test_vcenter/lib/python2.7/site-packages/pyVim/connect.py", line 552, in __FindSupportedVersion
    sslContext)
  File "/Users/tao-xu/.virtualenvs/test_vcenter/lib/python2.7/site-packages/pyVim/connect.py", line 472, in __GetServiceVersionDescription
    tree = __GetElementTreeFromUrl(url, sslContext)
  File "/Users/tao-xu/.virtualenvs/test_vcenter/lib/python2.7/site-packages/pyVim/connect.py", line 438, in __GetElementTreeFromUrl
    sock = requests.get(url, verify=False)
  File "/Users/tao-xu/.virtualenvs/test_vcenter/lib/python2.7/site-packages/requests/api.py", line 67, in get
    return request('get', url, params=params, **kwargs)
  File "/Users/tao-xu/.virtualenvs/test_vcenter/lib/python2.7/site-packages/requests/api.py", line 53, in request
    return session.request(method=method, url=url, **kwargs)
  File "/Users/tao-xu/.virtualenvs/test_vcenter/lib/python2.7/site-packages/requests/sessions.py", line 468, in request
    resp = self.send(prep, **send_kwargs)
  File "/Users/tao-xu/.virtualenvs/test_vcenter/lib/python2.7/site-packages/requests/sessions.py", line 576, in send
    r = adapter.send(request, **kwargs)
  File "/Users/tao-xu/.virtualenvs/test_vcenter/lib/python2.7/site-packages/requests/adapters.py", line 437, in send
    raise ConnectionError(e, request=request)
ConnectionError: HTTPSConnectionPool(host='172.16.0.4', port=443): Max retries exceeded with url: //sdk/vimServiceVersions.xml (Caused by NewConnectionError('<requests.packages.urllib3.connection.VerifiedHTTPSConnection object at 0x10a6b1750>: Failed to establish a new connection: [Errno 60] Operation timed out',))

INFO 2016-06-17 14:35:35,458 tasks 89513 140735228776448 /Users/tao-xu/Downloads/vCenter/paas/applications/stat/tasks.py 84 vm_to_tpl start vm:None to tpl:CDS-OS-Redhat5.9-64bit-General-V00284716-33b4-11e6-bc0e-507b9d5bc407
INFO 2016-06-17 14:36:50,828 tasks 89513 140735228776448 /Users/tao-xu/Downloads/vCenter/paas/applications/stat/tasks.py 111 vm_to_tpl vm_to_tpl when catch exception:Traceback (most recent call last):
  File "/Users/tao-xu/Downloads/vCenter/paas/applications/stat/tasks.py", line 86, in vm_to_tpl
    datacenter_name=data_center, cluster=cluster, datastore=data_store)
  File "/Users/tao-xu/Downloads/vCenter/paas/libs/vcenter.py", line 318, in vm_to_template
    si = connect_vcenter(host=host, username=username, password=password)
  File "/Users/tao-xu/Downloads/vCenter/paas/libs/vcenter.py", line 133, in connect_vcenter
    si = SmartConnect(host=host, user=username, pwd=password, port=443, sslContext=CONTEXT)
  File "/Users/tao-xu/.virtualenvs/test_vcenter/lib/python2.7/site-packages/pyVim/connect.py", line 663, in SmartConnect
    sslContext)
  File "/Users/tao-xu/.virtualenvs/test_vcenter/lib/python2.7/site-packages/pyVim/connect.py", line 552, in __FindSupportedVersion
    sslContext)
  File "/Users/tao-xu/.virtualenvs/test_vcenter/lib/python2.7/site-packages/pyVim/connect.py", line 472, in __GetServiceVersionDescription
    tree = __GetElementTreeFromUrl(url, sslContext)
  File "/Users/tao-xu/.virtualenvs/test_vcenter/lib/python2.7/site-packages/pyVim/connect.py", line 438, in __GetElementTreeFromUrl
    sock = requests.get(url, verify=False)
  File "/Users/tao-xu/.virtualenvs/test_vcenter/lib/python2.7/site-packages/requests/api.py", line 67, in get
    return request('get', url, params=params, **kwargs)
  File "/Users/tao-xu/.virtualenvs/test_vcenter/lib/python2.7/site-packages/requests/api.py", line 53, in request
    return session.request(method=method, url=url, **kwargs)
  File "/Users/tao-xu/.virtualenvs/test_vcenter/lib/python2.7/site-packages/requests/sessions.py", line 468, in request
    resp = self.send(prep, **send_kwargs)
  File "/Users/tao-xu/.virtualenvs/test_vcenter/lib/python2.7/site-packages/requests/sessions.py", line 576, in send
    r = adapter.send(request, **kwargs)
  File "/Users/tao-xu/.virtualenvs/test_vcenter/lib/python2.7/site-packages/requests/adapters.py", line 437, in send
    raise ConnectionError(e, request=request)
ConnectionError: HTTPSConnectionPool(host='172.16.0.4', port=443): Max retries exceeded with url: //sdk/vimServiceVersions.xml (Caused by NewConnectionError('<requests.packages.urllib3.connection.VerifiedHTTPSConnection object at 0x10a70f810>: Failed to establish a new connection: [Errno 60] Operation timed out',))

INFO 2016-06-17 14:45:26,675 tasks 89513 140735228776448 /Users/tao-xu/Downloads/vCenter/paas/applications/stat/tasks.py 84 vm_to_tpl start vm:None to tpl:CDS-OS-Redhat5.9-64bit-General-V00284716-33b4-11e6-bc0e-507b9d5bc407
INFO 2016-06-17 14:46:42,390 tasks 89513 140735228776448 /Users/tao-xu/Downloads/vCenter/paas/applications/stat/tasks.py 111 vm_to_tpl vm_to_tpl when catch exception:Traceback (most recent call last):
  File "/Users/tao-xu/Downloads/vCenter/paas/applications/stat/tasks.py", line 86, in vm_to_tpl
    datacenter_name=data_center, cluster=cluster, datastore=data_store)
  File "/Users/tao-xu/Downloads/vCenter/paas/libs/vcenter.py", line 318, in vm_to_template
    si = connect_vcenter(host=host, username=username, password=password)
  File "/Users/tao-xu/Downloads/vCenter/paas/libs/vcenter.py", line 133, in connect_vcenter
    si = SmartConnect(host=host, user=username, pwd=password, port=443, sslContext=CONTEXT)
  File "/Users/tao-xu/.virtualenvs/test_vcenter/lib/python2.7/site-packages/pyVim/connect.py", line 663, in SmartConnect
    sslContext)
  File "/Users/tao-xu/.virtualenvs/test_vcenter/lib/python2.7/site-packages/pyVim/connect.py", line 552, in __FindSupportedVersion
    sslContext)
  File "/Users/tao-xu/.virtualenvs/test_vcenter/lib/python2.7/site-packages/pyVim/connect.py", line 472, in __GetServiceVersionDescription
    tree = __GetElementTreeFromUrl(url, sslContext)
  File "/Users/tao-xu/.virtualenvs/test_vcenter/lib/python2.7/site-packages/pyVim/connect.py", line 438, in __GetElementTreeFromUrl
    sock = requests.get(url, verify=False)
  File "/Users/tao-xu/.virtualenvs/test_vcenter/lib/python2.7/site-packages/requests/api.py", line 67, in get
    return request('get', url, params=params, **kwargs)
  File "/Users/tao-xu/.virtualenvs/test_vcenter/lib/python2.7/site-packages/requests/api.py", line 53, in request
    return session.request(method=method, url=url, **kwargs)
  File "/Users/tao-xu/.virtualenvs/test_vcenter/lib/python2.7/site-packages/requests/sessions.py", line 468, in request
    resp = self.send(prep, **send_kwargs)
  File "/Users/tao-xu/.virtualenvs/test_vcenter/lib/python2.7/site-packages/requests/sessions.py", line 576, in send
    r = adapter.send(request, **kwargs)
  File "/Users/tao-xu/.virtualenvs/test_vcenter/lib/python2.7/site-packages/requests/adapters.py", line 437, in send
    raise ConnectionError(e, request=request)
ConnectionError: HTTPSConnectionPool(host='172.16.0.4', port=443): Max retries exceeded with url: //sdk/vimServiceVersions.xml (Caused by NewConnectionError('<requests.packages.urllib3.connection.VerifiedHTTPSConnection object at 0x10a70fa90>: Failed to establish a new connection: [Errno 60] Operation timed out',))

